<!--URDF generated by ONSHAPE BY PTC INC, 1.217-->
<robot name="urdf_top_assembly">
    <link name="base">
        <inertial>
            <mass value="0.873654" />
            <origin xyz="-0.0147678 0.099976 0.0250383" rpy="0 -0 0" />
            <inertia ixx="0.00157059" ixy="-9.4753e-07" ixz="2.04071e-07" iyy="0.000678307" iyz="2.44292e-07" izz="0.00169404" />
        </inertial>
        <visual>
            <origin xyz="-0.177501 0.0535995 -0.0124966" rpy="0 -0 0" />
            <geometry>
                <mesh filename="package://urdf_top_assembly/meshes/Base.stl" scale="1 1 1" />
            </geometry>
            <material name="0.647059_0.647059_0.647059_0.000000_0.000000">
                <color rgba="0.647059 0.647059 0.647059 1" />
            </material>
        </visual>
    </link>
    <link name="base_1">
        <inertial>
            <mass value="0.873654" />
            <origin xyz="-0.0247678 -2.4007e-05 3.82998e-05" rpy="0 -0 0" />
            <inertia ixx="0.00157059" ixy="-9.4753e-07" ixz="2.04071e-07" iyy="0.000678307" iyz="2.44292e-07" izz="0.00169404" />
        </inertial>
        <visual>
            <origin xyz="-0.187501 -0.0464005 -0.0374966" rpy="0 -0 0" />
            <geometry>
                <mesh filename="package://urdf_top_assembly/meshes/Base.stl" scale="1 1 1" />
            </geometry>
            <material name="0.647059_0.647059_0.647059_0.000000_0.000000">
                <color rgba="0.647059 0.647059 0.647059 1" />
            </material>
        </visual>
    </link>
    <link name="gripper">
        <inertial>
            <mass value="0.553219" />
            <origin xyz="0.0139643 0.0466488 -0.102413" rpy="0 -0 0" />
            <inertia ixx="0.000409669" ixy="5.44941e-07" ixz="7.91268e-07" iyy="0.000324942" iyz="-4.83959e-06" izz="0.000369249" />
        </inertial>
        <visual>
            <origin xyz="0 0 0" rpy="0 -0 0" />
            <geometry>
                <mesh filename="package://urdf_top_assembly/meshes/Gripper.stl" scale="1 1 1" />
            </geometry>
            <material name="0.647059_0.647059_0.647059_0.000000_0.000000">
                <color rgba="0.647059 0.647059 0.647059 1" />
            </material>
        </visual>
    </link>
    <link name="gripper_1">
        <inertial>
            <mass value="0.553219" />
            <origin xyz="-3.57064e-05 0.000249371 -0.0293133" rpy="0 -0 0" />
            <inertia ixx="0.000409669" ixy="5.44941e-07" ixz="7.91268e-07" iyy="0.000324942" iyz="-4.83959e-06" izz="0.000369249" />
        </inertial>
        <visual>
            <origin xyz="-0.014 -0.0463995 0.0731" rpy="0 -0 0" />
            <geometry>
                <mesh filename="package://urdf_top_assembly/meshes/Gripper.stl" scale="1 1 1" />
            </geometry>
            <material name="0.647059_0.647059_0.647059_0.000000_0.000000">
                <color rgba="0.647059 0.647059 0.647059 1" />
            </material>
        </visual>
    </link>
    <link name="link1">
        <inertial>
            <mass value="0.101218" />
            <origin xyz="-0.0233636 -0.00172503 -0.00727828" rpy="0 -0 0" />
            <inertia ixx="0.000114689" ixy="-4.62759e-06" ixz="-1.3427e-05" iyy="4.76603e-05" iyz="-2.58724e-06" izz="0.000125996" />
        </inertial>
        <visual>
            <origin xyz="-0.119501 -0.0464 -0.0374968" rpy="0 -0 0" />
            <geometry>
                <mesh filename="package://urdf_top_assembly/meshes/link1.stl" scale="1 1 1" />
            </geometry>
            <material name="0.647059_0.647059_0.647059_0.000000_0.000000">
                <color rgba="0.647059 0.647059 0.647059 1" />
            </material>
        </visual>
    </link>
    <link name="link1_1">
        <inertial>
            <mass value="0.101218" />
            <origin xyz="0.0961372 0.044675 0.0302185" rpy="0 -0 0" />
            <inertia ixx="0.000114689" ixy="-4.62759e-06" ixz="-1.3427e-05" iyy="4.76603e-05" iyz="-2.58724e-06" izz="0.000125996" />
        </inertial>
        <visual>
            <origin xyz="0 0 0" rpy="0 -0 0" />
            <geometry>
                <mesh filename="package://urdf_top_assembly/meshes/link1.stl" scale="1 1 1" />
            </geometry>
            <material name="0.647059_0.647059_0.647059_0.000000_0.000000">
                <color rgba="0.647059 0.647059 0.647059 1" />
            </material>
        </visual>
    </link>
    <link name="link2">
        <inertial>
            <mass value="1.52608" />
            <origin xyz="0.0741346 0.0471247 0.146663" rpy="0 -0 0" />
            <inertia ixx="0.0152377" ixy="-1.14963e-08" ixz="-4.49806e-07" iyy="0.0151654" iyz="3.2469e-06" izz="0.00083113" />
        </inertial>
        <visual>
            <origin xyz="0 0 0" rpy="0 -0 0" />
            <geometry>
                <mesh filename="package://urdf_top_assembly/meshes/link2.stl" scale="1 1 1" />
            </geometry>
            <material name="0.647059_0.647059_0.647059_0.000000_0.000000">
                <color rgba="0.647059 0.647059 0.647059 1" />
            </material>
        </visual>
    </link>
    <link name="link2_1">
        <inertial>
            <mass value="1.52608" />
            <origin xyz="0.000134495 0.0336247 0.129165" rpy="0 -0 0" />
            <inertia ixx="0.0152377" ixy="-1.14963e-08" ixz="-4.49806e-07" iyy="0.0151654" iyz="3.2469e-06" izz="0.00083113" />
        </inertial>
        <visual>
            <origin xyz="-0.0740001 -0.0135 -0.0174977" rpy="0 -0 0" />
            <geometry>
                <mesh filename="package://urdf_top_assembly/meshes/link2.stl" scale="1 1 1" />
            </geometry>
            <material name="0.647059_0.647059_0.647059_0.000000_0.000000">
                <color rgba="0.647059 0.647059 0.647059 1" />
            </material>
        </visual>
    </link>
    <link name="link3">
        <inertial>
            <mass value="0.982553" />
            <origin xyz="-0.0556042 0.0357986 -0.135083" rpy="0 -0 0" />
            <inertia ixx="0.00758945" ixy="4.36076e-06" ixz="-0.00064069" iyy="0.00763097" iyz="-1.09984e-05" izz="0.000937606" />
        </inertial>
        <visual>
            <origin xyz="-0.0740003 -0.01145 -0.281499" rpy="0 -0 0" />
            <geometry>
                <mesh filename="package://urdf_top_assembly/meshes/link3.stl" scale="1 1 1" />
            </geometry>
            <material name="0.647059_0.647059_0.647059_0.000000_0.000000">
                <color rgba="0.647059 0.647059 0.647059 1" />
            </material>
        </visual>
    </link>
    <link name="link3_1">
        <inertial>
            <mass value="0.982553" />
            <origin xyz="0.0183961 0.0472486 0.146416" rpy="0 -0 0" />
            <inertia ixx="0.00758945" ixy="4.36076e-06" ixz="-0.00064069" iyy="0.00763097" iyz="-1.09984e-05" izz="0.000937606" />
        </inertial>
        <visual>
            <origin xyz="0 0 0" rpy="0 -0 0" />
            <geometry>
                <mesh filename="package://urdf_top_assembly/meshes/link3.stl" scale="1 1 1" />
            </geometry>
            <material name="0.647059_0.647059_0.647059_0.000000_0.000000">
                <color rgba="0.647059 0.647059 0.647059 1" />
            </material>
        </visual>
    </link>
    <link name="link4">
        <inertial>
            <mass value="0.462165" />
            <origin xyz="-0.0410956 0.045226 -0.0210545" rpy="0 -0 0" />
            <inertia ixx="0.000473594" ixy="3.00819e-05" ixz="-0.000238801" iyy="0.000764022" iyz="2.9261e-05" izz="0.000604492" />
        </inertial>
        <visual>
            <origin xyz="0 0 0" rpy="0 -0 0" />
            <geometry>
                <mesh filename="package://urdf_top_assembly/meshes/link4.stl" scale="1 1 1" />
            </geometry>
            <material name="0.647059_0.647059_0.647059_0.000000_0.000000">
                <color rgba="0.647059 0.647059 0.647059 1" />
            </material>
        </visual>
    </link>
    <link name="link4_1">
        <inertial>
            <mass value="0.462165" />
            <origin xyz="-0.0548959 -0.0350242 -0.0575534" rpy="0 -0 0" />
            <inertia ixx="0.000473594" ixy="3.00819e-05" ixz="-0.000238801" iyy="0.000764022" iyz="2.9261e-05" izz="0.000604492" />
        </inertial>
        <visual>
            <origin xyz="-0.0138003 -0.0802502 -0.0364989" rpy="0 -0 0" />
            <geometry>
                <mesh filename="package://urdf_top_assembly/meshes/link4.stl" scale="1 1 1" />
            </geometry>
            <material name="0.647059_0.647059_0.647059_0.000000_0.000000">
                <color rgba="0.647059 0.647059 0.647059 1" />
            </material>
        </visual>
    </link>
    <link name="link5">
        <inertial>
            <mass value="0.395939" />
            <origin xyz="0.0110096 0.0463995 -0.0379035" rpy="0 -0 0" />
            <inertia ixx="0.000178186" ixy="-8.62455e-11" ixz="1.2215e-05" iyy="0.000213775" iyz="2.54089e-10" izz="0.000176683" />
        </inertial>
        <visual>
            <origin xyz="0 0 0" rpy="0 -0 0" />
            <geometry>
                <mesh filename="package://urdf_top_assembly/meshes/link5.stl" scale="1 1 1" />
            </geometry>
            <material name="0.647059_0.647059_0.647059_0.000000_0.000000">
                <color rgba="0.647059 0.647059 0.647059 1" />
            </material>
        </visual>
    </link>
    <link name="link5_1">
        <inertial>
            <mass value="0.403307" />
            <origin xyz="0.0375847 -3.55003e-05 -0.000825911" rpy="0 -0 0" />
            <inertia ixx="0.000184284" ixy="2.10549e-07" ixz="1.29173e-05" iyy="0.000219791" iyz="-3.49657e-07" izz="0.000181053" />
        </inertial>
        <visual>
            <origin xyz="0.0265 -0.0463995 0.0375" rpy="0 -0 0" />
            <geometry>
                <mesh filename="package://urdf_top_assembly/meshes/link5_1.stl" scale="1 1 1" />
            </geometry>
            <material name="0.827451_0.623529_0.784314_0.000000_0.000000">
                <color rgba="0.827451 0.623529 0.784314 1" />
            </material>
        </visual>
    </link>
    <link name="root" />
    <link name="tip_left">
        <inertial>
            <mass value="0.069657" />
            <origin xyz="0.014584 -0.042586 -0.0228318" rpy="0 -0 0" />
            <inertia ixx="5.14494e-05" ixy="1.10836e-05" ixz="1.00197e-05" iyy="4.99137e-05" iyz="-1.14425e-05" izz="4.79405e-05" />
        </inertial>
        <visual>
            <origin xyz="0.00999321 -0.0914614 0.129783" rpy="0 -0 0" />
            <geometry>
                <mesh filename="package://urdf_top_assembly/meshes/tip_left.stl" scale="1 1 1" />
            </geometry>
            <material name="0.647059_0.647059_0.647059_0.000000_0.000000">
                <color rgba="0.647059 0.647059 0.647059 1" />
            </material>
        </visual>
    </link>
    <link name="tip_left_1">
        <inertial>
            <mass value="0.069657" />
            <origin xyz="0.00459082 0.0488754 -0.152614" rpy="0 -0 0" />
            <inertia ixx="5.14494e-05" ixy="1.10836e-05" ixz="1.00197e-05" iyy="4.99137e-05" iyz="-1.14425e-05" izz="4.79405e-05" />
        </inertial>
        <visual>
            <origin xyz="0 0 0" rpy="0 -0 0" />
            <geometry>
                <mesh filename="package://urdf_top_assembly/meshes/tip_left.stl" scale="1 1 1" />
            </geometry>
            <material name="0.647059_0.647059_0.647059_0.000000_0.000000">
                <color rgba="0.647059 0.647059 0.647059 1" />
            </material>
        </visual>
    </link>
    <link name="tip_left_2">
        <inertial>
            <mass value="5.33252e-05" />
            <origin xyz="0.00435537 0.0464015 -0.13135" rpy="0 -0 0" />
            <inertia ixx="5.04561e-10" ixy="9.70952e-14" ixz="0" iyy="5.12002e-10" iyz="0" izz="3.67135e-11" />
        </inertial>
        <visual>
            <origin xyz="0 0 0" rpy="0 -0 0" />
            <geometry>
                <mesh filename="package://urdf_top_assembly/meshes/tip_left_1.stl" scale="1 1 1" />
            </geometry>
            <material name="0.647059_0.647059_0.647059_0.000000_0.000000">
                <color rgba="0.647059 0.647059 0.647059 1" />
            </material>
        </visual>
    </link>
    <link name="tip_right">
        <inertial>
            <mass value="0.069657" />
            <origin xyz="0.0234092 0.0439235 -0.152614" rpy="0 -0 0" />
            <inertia ixx="5.14494e-05" ixy="1.10836e-05" ixz="-1.00197e-05" iyy="4.99137e-05" iyz="1.14425e-05" izz="4.79405e-05" />
        </inertial>
        <visual>
            <origin xyz="0 0 0" rpy="0 -0 0" />
            <geometry>
                <mesh filename="package://urdf_top_assembly/meshes/tip_right.stl" scale="1 1 1" />
            </geometry>
            <material name="0.647059_0.647059_0.647059_0.000000_0.000000">
                <color rgba="0.647059 0.647059 0.647059 1" />
            </material>
        </visual>
    </link>
    <link name="tip_right_1">
        <inertial>
            <mass value="0.069657" />
            <origin xyz="-0.014584 0.042586 -0.0228318" rpy="0 -0 0" />
            <inertia ixx="5.14494e-05" ixy="1.10836e-05" ixz="-1.00197e-05" iyy="4.99137e-05" iyz="1.14425e-05" izz="4.79405e-05" />
        </inertial>
        <visual>
            <origin xyz="-0.0379932 -0.00133753 0.129783" rpy="0 -0 0" />
            <geometry>
                <mesh filename="package://urdf_top_assembly/meshes/tip_right.stl" scale="1 1 1" />
            </geometry>
            <material name="0.647059_0.647059_0.647059_0.000000_0.000000">
                <color rgba="0.647059 0.647059 0.647059 1" />
            </material>
        </visual>
    </link>
    <link name="tip_right_2">
        <inertial>
            <mass value="5.33252e-05" />
            <origin xyz="0.0236446 0.0463975 -0.13135" rpy="0 -0 0" />
            <inertia ixx="5.04561e-10" ixy="9.70952e-14" ixz="0" iyy="5.12002e-10" iyz="0" izz="3.67135e-11" />
        </inertial>
        <visual>
            <origin xyz="0 0 0" rpy="0 -0 0" />
            <geometry>
                <mesh filename="package://urdf_top_assembly/meshes/tip_right_1.stl" scale="1 1 1" />
            </geometry>
            <material name="0.647059_0.647059_0.647059_0.000000_0.000000">
                <color rgba="0.647059 0.647059 0.647059 1" />
            </material>
        </visual>
    </link>
    <joint name="dof_joint0" type="revolute">
        <origin xyz="0 0 0" rpy="0 1.5708 -3.14159" />
        <axis xyz="-1 0 0" />
        <parent link="root" />
        <child link="base_1" />
        <limit effort="1" velocity="1" lower="0" upper="0" />
    </joint>
    <joint name="dof_joint1" type="revolute">
        <origin xyz="-0.068 -1.33927e-15 -9.44574e-16" rpy="2.44776e-17 -7.21645e-16 -3.44415e-16" />
        <axis xyz="-1 0 0" />
        <parent link="base_1" />
        <child link="link1" />
        <limit effort="1" velocity="1" lower="-2.61799" upper="3.14159" />
    </joint>
    <joint name="dof_joint2" type="revolute">
        <origin xyz="-0.0455 -0.0329 -0.02" rpy="4.47367e-16 5.42424e-16 4.00074e-15" />
        <axis xyz="-3.58252e-15 -1 3.35753e-16" />
        <parent link="link1" />
        <child link="link2_1" />
        <limit effort="1" velocity="1" lower="0" upper="3.66519" />
    </joint>
    <joint name="dof_joint3" type="revolute">
        <origin xyz="4.08431e-07 -0.00205 0.264" rpy="-1.08814e-14 5.62765e-16 6.86704e-16" />
        <axis xyz="4.54273e-15 1 1.04275e-14" />
        <parent link="link2_1" />
        <child link="link3" />
        <limit effort="1" velocity="1" lower="0" upper="3.14159" />
    </joint>
    <joint name="dof_joint4" type="revolute">
        <origin xyz="-0.0600003 0.0688 -0.244999" rpy="1.04275e-14 3.83027e-15 -4.34003e-15" />
        <axis xyz="0 1 0" />
        <parent link="link3" />
        <child link="link4_1" />
        <limit effort="1" velocity="1" lower="-1.69297" upper="1.5708" />
    </joint>
    <joint name="dof_joint5" type="revolute">
        <origin xyz="-0.0403003 -0.0338507 -0.0739989" rpy="-1.03641e-14 -1.15907e-14 6.37337e-29" />
        <axis xyz="-1 0 0" />
        <parent link="link4_1" />
        <child link="link5_1" />
        <limit effort="1" velocity="1" lower="-1.5708" upper="1.5708" />
    </joint>
    <joint name="dof_joint6" type="revolute">
        <origin xyz="0.0404996 2.39858e-07 -0.0356" rpy="2.20639e-29 -7.27366e-16 4.6601e-15" />
        <axis xyz="-1.46014e-15 -2.40808e-14 1" />
        <parent link="link5_1" />
        <child link="gripper_1" />
        <limit effort="1" velocity="1" lower="-2.0944" upper="2.0944" />
    </joint>
    <joint name="dof_joint7" type="prismatic">
        <origin xyz="0.0239931 -0.0445119 -0.0566829" rpy="-9.65016e-15 -9.99201e-16 3.14159" />
        <axis xyz="6.86541e-15 1 0" />
        <parent link="gripper_1" />
        <child link="tip_left" />
        <limit effort="1" velocity="1" lower="-0.04695" upper="1.36187e-15" />
    </joint>
    <joint name="dof_joint8" type="prismatic">
        <origin xyz="-0.0239931 0.0445119 -0.0566829" rpy="-9.29241e-15 -9.99201e-16 -3.14159" />
        <axis xyz="-6.86541e-15 -1 0" />
        <parent link="gripper_1" />
        <child link="tip_right_1" />
        <limit effort="1" velocity="1" lower="-0.04695" upper="0" />
    </joint>
    <joint name="分组_1_fastened_joint" type="fixed">
        <origin xyz="-0.177501 0.0535995 -0.0124966" rpy="0 -0 0" />
        <axis xyz="-0 -0 -1" />
        <parent link="base" />
        <child link="link4" />
    </joint>
    <joint name="分组_1_fastened_joint_1" type="fixed">
        <origin xyz="0 0 0" rpy="0 -0 0" />
        <axis xyz="0 0 1" />
        <parent link="link3_1" />
        <child link="link1_1" />
    </joint>
    <joint name="分组_1_fastened_joint_2" type="fixed">
        <origin xyz="-0.177501 0.0535995 -0.0124966" rpy="0 -0 0" />
        <axis xyz="0 0 1" />
        <parent link="base" />
        <child link="tip_right_2" />
    </joint>
    <joint name="分组_1_fastened_joint_3" type="fixed">
        <origin xyz="0 0 0" rpy="0 -0 0" />
        <axis xyz="0 0 1" />
        <parent link="link2" />
        <child link="link3_1" />
    </joint>
    <joint name="分组_1_fastened_joint_4" type="fixed">
        <origin xyz="0 0 0" rpy="0 -0 0" />
        <axis xyz="-0 -0 -1" />
        <parent link="link4" />
        <child link="link5" />
    </joint>
    <joint name="分组_1_fastened_joint_5" type="fixed">
        <origin xyz="0 0 0" rpy="0 -0 0" />
        <axis xyz="0 0 1" />
        <parent link="tip_right_2" />
        <child link="tip_left_2" />
    </joint>
    <joint name="分组_1_fastened_joint_6" type="fixed">
        <origin xyz="0 0 0" rpy="0 -0 0" />
        <axis xyz="0 0 1" />
        <parent link="link1_1" />
        <child link="gripper" />
    </joint>
    <joint name="分组_1_fastened_joint_7" type="fixed">
        <origin xyz="0 0 0" rpy="0 -0 0" />
        <axis xyz="0 0 1" />
        <parent link="tip_right" />
        <child link="tip_left_1" />
    </joint>
    <joint name="分组_1_fastened_joint_8" type="fixed">
        <origin xyz="0 0 0" rpy="0 -0 0" />
        <axis xyz="0 0 1" />
        <parent link="tip_left_2" />
        <child link="link2" />
    </joint>
    <joint name="分组_1_fastened_joint_9" type="fixed">
        <origin xyz="0 0 0" rpy="0 -0 0" />
        <axis xyz="0 0 1" />
        <parent link="gripper" />
        <child link="tip_right" />
    </joint>
    <joint name="紧固_2" type="fixed">
        <origin xyz="-0.01 -0.1 -0.025" rpy="6.60149e-34 6.16298e-33 2.03424e-66" />
        <axis xyz="-1 0 0" />
        <parent link="base_1" />
        <child link="base" />
    </joint>
</robot>
