<mujoco model="yam_pro">
  <compiler angle="radian" meshdir="assets"/>

  <asset>
    <mesh name="base"  file="base.stl"/>
    <mesh name="link1" file="link1.stl"/>
    <mesh name="link2" file="link2.stl"/>
    <mesh name="link3" file="link3.stl"/>
    <mesh name="link4" file="link4.stl"/>
    <mesh name="link5" file="link5.stl"/>
  </asset>

  <worldbody>
    <body name="base" pos="0 0 0" quat="1 0 0 0">
      <inertial pos="-3.83908409137e-05 2.40068981265e-05 0.0247677998591" quat="0.49938114478697948 0.50073961447194104 -0.50008727960892496 -0.4997909798136444" mass="0.873654" diaginertia="0.00067830593494507517 0.0015705906697095881 0.0016940403953453372"/>
      <geom pos="0.0374957881421 0.0464005994986 0.187501137731" quat="9.381838724410722e-07 0.70710807985877822 9.3818731858953273e-07 -0.70710548251068706" type="mesh" rgba="0.647059 0.647059 0.647059 1" mesh="base"/>
      <body name="link1" pos="-2.49777947114e-07 0 0.0679999999995" quat="9.3818411501280666e-07 0.70710807985877822 9.381875611610837e-07 -0.70710548251068706">
        <inertial pos="-0.0233636 -0.00172503 -0.00727828" quat="-0.64524361769733818 -0.21204348917963081 0.19681281961670494 0.70708057995669871" mass="0.101218" diaginertia="4.7181498384517786e-05 0.00010625072855078136 0.0001349130730647009"/>
        <joint name="joint1" pos="0 0 0" axis="-1 0 0" type="hinge" range="-2.61799 3.14159" actuatorfrcrange="-10 10"/>
        <geom pos="-0.119501 -0.0464 -0.0374968" quat="1 0 0 0" type="mesh" rgba="0.647059 0.647059 0.647059 1" mesh="link1"/>
        <body name="link2" pos="-0.0455 -0.0329 -0.02" quat="1 1.6811750000000164e-16 -9.5581999999999982e-16 1.7303650000000003e-15">
          <inertial pos="0.000134495 0.0336247 0.129165" quat="-2.3368104685381288e-05 0.70711781939337348 -0.00013679904709816199 0.70709572918828534" mass="1.52608" diaginertia="0.0008311292504908298 0.015165400733604792 0.01523770001590438"/>
          <joint name="joint2" pos="0 0 0" axis="-3.58252e-15 -1 3.35753e-16" type="hinge" range="0 3.66519" actuatorfrcrange="-10 10"/>
          <geom pos="-0.0740001 -0.0135 -0.0174977" quat="1 0 0 0" type="mesh" rgba="0.647059 0.647059 0.647059 1" mesh="link2"/>
          <body name="link3" pos="4.08431e-07 -0.00205 0.264" quat="1 -5.3991000000000092e-15 2.8574349999999998e-14 3.2007050000015427e-16">
            <inertial pos="-0.0556042 0.0357986 -0.135083" quat="0.6673095083601458 -0.084819836562637627 0.73417432797379689 0.092150265989044328" mass="0.982553" diaginertia="0.00087644191886574482 0.0076296046064632606 0.0076519794746709975"/>
            <joint name="joint3" pos="0 0 0" axis="4.54273e-15 1 1.04275e-14" type="hinge" range="0 3.14159" actuatorfrcrange="-10 10"/>
            <geom pos="-0.0740003 -0.01145 -0.281499" quat="1 0 0 0" type="mesh" rgba="0.647059 0.647059 0.647059 1" mesh="link3"/>
            <body name="link4" pos="-0.0600003 0.0688 -0.244999" quat="1 5.2137499999999605e-15 -1.8263150000000013e-14 -2.1700149999999048e-15">
              <inertial pos="-0.0548959 -0.0350242 -0.0575534" quat="0.10060722133102601 0.94108569945662934 -0.07975559657973047 0.31284970530350159" mass="0.462165" diaginertia="0.00028778996544839548 0.00076643008992378317 0.00078788794462782174"/>
              <joint name="joint4" pos="0 0 0" axis="0 1 0" type="hinge" range="-1.69297 1.5708" actuatorfrcrange="-10 10"/>
              <geom pos="-0.0138003 -0.0802502 -0.0364989" quat="1 0 0 0" type="mesh" rgba="0.647059 0.647059 0.647059 1" mesh="link4"/>
              <body name="link5" pos="-0.0403003 -0.0338507 -0.0739989" quat="1 -4.1908100000000015e-15 -1.1163449999999929e-15 -1.6792100000000047e-15">
                <inertial pos="0.0375847 -3.55003e-05 -0.000825911" quat="0.64668614070190822 0.64239183561513957 0.28865586152813083 -0.29292927229031912" mass="0.403307" diaginertia="0.00016964735642963316 0.00019568620481229821 0.00021979443875806869"/>
                <joint name="joint5" pos="0 0 0" axis="1 0 0" type="hinge" range="-1.5708 1.5708" actuatorfrcrange="-10 10"/>
                <geom pos="0.0265 -0.0463995 0.0375" quat="1 0 0 0" type="mesh" rgba="0.827451 0.623529 0.784314 1" mesh="link5"/>
                <body name="link6" pos="0.0404996 2.39858e-07 -0.0356" quat="1 3.3970050000000036e-15 -8.7934999999998608e-16 4.0981150000000029e-15">
                  <inertial pos="0 0 0" mass="1e-6" diaginertia="1e-9 1e-9 1e-9"/>
                  <joint name="joint6" pos="0 0 0" axis="1.46014e-15 2.40808e-14 -1" type="hinge" range="-2.0944 2.0944" actuatorfrcrange="-10 10"/>
                </body>
              </body>
            </body>
          </body>
        </body>
      </body>
    </body>
  </worldbody>
</mujoco>
