<!--URDF generated by ONSHAPE BY PTC INC, 1.217-->
<robot name="urdf_top_assembly">
    <link name="base">
        <inertial>
            <mass value="0.873654" />
            <origin xyz="-0.0247678 -2.4007e-05 3.82998e-05" rpy="0 -0 0" />
            <inertia ixx="0.00157059" ixy="-9.4753e-07" ixz="2.04071e-07" iyy="0.000678307" iyz="2.44292e-07" izz="0.00169404" />
        </inertial>
        <visual>
            <origin xyz="-0.187501 -0.0464005 -0.0374966" rpy="0 -0 0" />
            <geometry>
                <mesh filename="package://urdf_top_assembly/meshes/Base.stl" scale="1 1 1" />
            </geometry>
            <material name="0.317647_0.121569_0.498039_0.000000_0.000000">
                <color rgba="0.317647 0.121569 0.498039 1" />
            </material>
        </visual>
    </link>
    <link name="gripper">
        <inertial>
            <mass value="0.553219" />
            <origin xyz="-3.57064e-05 0.000249371 -0.0293133" rpy="0 -0 0" />
            <inertia ixx="0.000409669" ixy="5.44941e-07" ixz="7.91268e-07" iyy="0.000324942" iyz="-4.83959e-06" izz="0.000369249" />
        </inertial>
        <visual>
            <origin xyz="-0.014 -0.0463995 0.0731" rpy="0 -0 0" />
            <geometry>
                <mesh filename="package://urdf_top_assembly/meshes/Gripper.stl" scale="1 1 1" />
            </geometry>
            <material name="0.109804_0.286275_0.011765_0.000000_0.000000">
                <color rgba="0.109804 0.286275 0.0117647 1" />
            </material>
        </visual>
    </link>
    <link name="link1">
        <inertial>
            <mass value="0.101218" />
            <origin xyz="-0.0233636 -0.00172503 -0.00727828" rpy="0 -0 0" />
            <inertia ixx="0.000114689" ixy="-4.62759e-06" ixz="-1.3427e-05" iyy="4.76603e-05" iyz="-2.58724e-06" izz="0.000125996" />
        </inertial>
        <visual>
            <origin xyz="-0.119501 -0.0464 -0.0374968" rpy="0 -0 0" />
            <geometry>
                <mesh filename="package://urdf_top_assembly/meshes/link1.stl" scale="1 1 1" />
            </geometry>
            <material name="0.725490_0.450980_0.317647_0.000000_0.000000">
                <color rgba="0.72549 0.45098 0.317647 1" />
            </material>
        </visual>
    </link>
    <link name="link2">
        <inertial>
            <mass value="1.46908" />
            <origin xyz="0.000134495 -0.0331253 0.129165" rpy="0 -0 0" />
            <inertia ixx="0.0146686" ixy="-1.1067e-08" ixz="-4.33007e-07" iyy="0.014599" iyz="3.12564e-06" izz="0.000800089" />
        </inertial>
        <visual>
            <origin xyz="-0.0740001 -0.08025 -0.0174977" rpy="0 -0 0" />
            <geometry>
                <mesh filename="package://urdf_top_assembly/meshes/link2.stl" scale="1 1 1" />
            </geometry>
            <material name="0.000000_0.400000_0.600000_0.000000_0.000000">
                <color rgba="0 0.4 0.6 1" />
            </material>
        </visual>
    </link>
    <link name="link3">
        <inertial>
            <mass value="0.982553" />
            <origin xyz="-0.0556042 -0.0340514 -0.135083" rpy="0 -0 0" />
            <inertia ixx="0.00758945" ixy="4.36076e-06" ixz="-0.00064069" iyy="0.00763097" iyz="-1.09984e-05" izz="0.000937606" />
        </inertial>
        <visual>
            <origin xyz="-0.0740003 -0.0813 -0.281499" rpy="0 -0 0" />
            <geometry>
                <mesh filename="package://urdf_top_assembly/meshes/link3.stl" scale="1 1 1" />
            </geometry>
            <material name="0.552941_0.580392_0.203922_0.000000_0.000000">
                <color rgba="0.552941 0.580392 0.203922 1" />
            </material>
        </visual>
    </link>
    <link name="link4">
        <inertial>
            <mass value="0.462165" />
            <origin xyz="-0.0550959 0.032726 -0.0575534" rpy="0 -0 0" />
            <inertia ixx="0.000473594" ixy="3.00819e-05" ixz="-0.000238801" iyy="0.000764022" iyz="2.9261e-05" izz="0.000604492" />
        </inertial>
        <visual>
            <origin xyz="-0.0140003 -0.0125 -0.0364989" rpy="0 -0 0" />
            <geometry>
                <mesh filename="package://urdf_top_assembly/meshes/link4.stl" scale="1 1 1" />
            </geometry>
            <material name="0.545098_0.525490_0.419608_0.000000_0.000000">
                <color rgba="0.545098 0.52549 0.419608 1" />
            </material>
        </visual>
    </link>
    <link name="link5">
        <inertial>
            <mass value="0.403307" />
            <origin xyz="0.0375847 -3.55003e-05 -0.000825911" rpy="0 -0 0" />
            <inertia ixx="0.000184284" ixy="2.10549e-07" ixz="1.29173e-05" iyy="0.000219791" iyz="-3.49657e-07" izz="0.000181053" />
        </inertial>
        <visual>
            <origin xyz="0.0265 -0.0463995 0.0375" rpy="0 -0 0" />
            <geometry>
                <mesh filename="package://urdf_top_assembly/meshes/link5.stl" scale="1 1 1" />
            </geometry>
            <material name="0.827451_0.623529_0.784314_0.000000_0.000000">
                <color rgba="0.827451 0.623529 0.784314 1" />
            </material>
        </visual>
    </link>
    <link name="root" />
    <link name="tip_left">
        <inertial>
            <mass value="0.069657" />
            <origin xyz="0.014584 -0.042586 -0.0228318" rpy="0 -0 0" />
            <inertia ixx="5.14494e-05" ixy="1.10836e-05" ixz="1.00197e-05" iyy="4.99137e-05" iyz="-1.14425e-05" izz="4.79405e-05" />
        </inertial>
        <visual>
            <origin xyz="0.00999321 -0.0914614 0.129783" rpy="0 -0 0" />
            <geometry>
                <mesh filename="package://urdf_top_assembly/meshes/tip_left.stl" scale="1 1 1" />
            </geometry>
            <material name="0.596078_0.788235_0.921569_0.000000_0.000000">
                <color rgba="0.596078 0.788235 0.921569 1" />
            </material>
        </visual>
    </link>
    <link name="tip_right">
        <inertial>
            <mass value="0.069657" />
            <origin xyz="-0.014584 0.042586 -0.0228318" rpy="0 -0 0" />
            <inertia ixx="5.14494e-05" ixy="1.10836e-05" ixz="-1.00197e-05" iyy="4.99137e-05" iyz="1.14425e-05" izz="4.79405e-05" />
        </inertial>
        <visual>
            <origin xyz="-0.0379932 -0.00133753 0.129783" rpy="0 -0 0" />
            <geometry>
                <mesh filename="package://urdf_top_assembly/meshes/tip_right.stl" scale="1 1 1" />
            </geometry>
            <material name="0.596078_0.788235_0.921569_0.000000_0.000000">
                <color rgba="0.596078 0.788235 0.921569 1" />
            </material>
        </visual>
    </link>
    <joint name="dof_joint0" type="revolute">
        <origin xyz="0 0 0" rpy="0 1.5708 1.5708" />
        <axis xyz="-1 0 0" />
        <parent link="root" />
        <child link="base" />
        <limit effort="1" velocity="1" lower="0" upper="0" />
    </joint>
    <joint name="dof_joint1" type="revolute">
        <origin xyz="-0.068 -6.80012e-16 -5.41234e-16" rpy="8.32667e-17 2.01874e-17 -3.6657e-17" />
        <axis xyz="-1 0 0" />
        <parent link="base" />
        <child link="link1" />
        <limit effort="1" velocity="1" lower="-2.61799" upper="3.14159" />
    </joint>
    <joint name="dof_joint2" type="revolute">
        <origin xyz="-0.0455 -0.0339 -0.02" rpy="4.86604e-16 3.99049e-14 -3.14159" />
        <axis xyz="3.58252e-15 1 -3.2007e-16" />
        <parent link="link1" />
        <child link="link2" />
        <limit effort="1" velocity="1" lower="0" upper="3.66519" />
    </joint>
    <joint name="dof_joint3" type="revolute">
        <origin xyz="4.08431e-07 -0.0688 0.264" rpy="-1.01074e-14 7.11653e-14 -3.14159" />
        <axis xyz="4.54273e-15 1 1.04275e-14" />
        <parent link="link2" />
        <child link="link3" />
        <limit effort="1" velocity="1" lower="0" upper="3.14159" />
    </joint>
    <joint name="dof_joint4" type="revolute">
        <origin xyz="-0.0600003 -0.0688 -0.244999" rpy="1.03997e-14 -8.62366e-14 -4.39823e-15" />
        <axis xyz="0 1 0" />
        <parent link="link3" />
        <child link="link4" />
        <limit effort="1" velocity="1" lower="-1.69297" upper="1.5708" />
    </joint>
    <joint name="dof_joint5" type="revolute">
        <origin xyz="-0.0405003 0.0338995 -0.0739989" rpy="-2.58127e-15 -1.37665e-15 -1.04686e-15" />
        <axis xyz="-1 0 0" />
        <parent link="link4" />
        <child link="link5" />
        <limit effort="1" velocity="1" lower="-1.5708" upper="1.5708" />
    </joint>
    <joint name="dof_joint6" type="revolute">
        <origin xyz="0.0404996 2.39858e-07 -0.0356" rpy="1.00451e-15 -4.22055e-16 -1.11022e-16" />
        <axis xyz="-1.46014e-15 -2.40808e-14 1" />
        <parent link="link5" />
        <child link="gripper" />
        <limit effort="1" velocity="1" lower="-2.0944" upper="2.0944" />
    </joint>
    <joint name="dof_joint7" type="prismatic">
        <origin xyz="-0.0239931 0.0445119 -0.0566829" rpy="1.08798e-14 2.77556e-15 5.77825e-15" />
        <axis xyz="6.86541e-15 1 0" />
        <parent link="gripper" />
        <child link="tip_left" />
        <limit effort="1" velocity="1" lower="-0.04695" upper="0" />
    </joint>
    <joint name="dof_joint8" type="prismatic">
        <origin xyz="0.0239931 -0.0445119 -0.0566829" rpy="2.05045e-15 1.32394e-14 -3.16199e-14" />
        <axis xyz="-6.86541e-15 -1 0" />
        <parent link="gripper" />
        <child link="tip_right" />
        <limit effort="1" velocity="1" lower="-0.04695" upper="0" />
    </joint>
</robot>
