<mujoco model="yam">
  <compiler angle="radian" meshdir="assets"/>

  <asset>
    <mesh name="base"  file="base.stl"/>
    <mesh name="link1" file="link1.stl"/>
    <mesh name="link2" file="link2.stl"/>
    <mesh name="link3" file="link3.stl"/>
    <mesh name="link4" file="link4.stl"/>
    <mesh name="link5" file="link5.stl"/>
  </asset>

  <worldbody>
    <body name="base" pos="0 0 0" quat="1 0 0 0">
      <inertial pos="-3.83908653914762e-05 2.40068589826393e-05 0.0247677998591499" quat="0.49938139958418276 0.50073986942030346 -0.50008702432797014 -0.49979072522514489" mass="0.873654" diaginertia="0.00067830593494507463 0.0015705906697095877 0.0016940403953453369"/>
      <geom pos="0.0374957408313106 0.0464006377298596 0.187501137731438" quat="-1.29867173464042e-06 -0.707108079858281 -1.29867650493682e-06 0.707105482510044" type="mesh" rgba="0.317647 0.121569 0.498039 1" mesh="base"/>
      <body name="link1" pos="-2.49777947129965e-07 -9.17402363407408e-13 0.0679999999995413" quat="-1.29867173464042e-06 -0.707108079858281 -1.29867650493682e-06 0.707105482510044">
        <inertial pos="-0.0233636 -0.00172503 -0.00727828" quat="0.64524361769733818 0.21204348917963084 -0.19681281961670499 -0.70708057995669871" mass="0.101218" diaginertia="4.7181498384517786e-05 0.00010625072855078136 0.0001349130730647009"/>
        <joint name="joint1" pos="0 0 0" axis="-1 0 0" type="hinge" range="-2.61799 3.14159" actuatorfrcrange="-10 10"/>
        <geom pos="-0.119501 -0.0464 -0.0374968" quat="1 0 0 0" type="mesh" rgba="0.72549 0.45098 0.317647 1" mesh="link1"/>
        <body name="link2" pos="-0.0455 -0.0339 -0.02" quat="1.32679489667753e-06 2.77554809002317e-17 8.97650368259094e-17 -0.99999999999912">
          <inertial pos="0.000134495 -0.0331253 0.129165" quat="2.3368140745090919e-05 -0.70711781940433771 0.00013679930974081874 -0.70709572917726871" mass="1.46908" diaginertia="0.00080008827848097137 0.014599000706208605 0.014668600015310418"/>
          <joint name="joint2" pos="0 0 0" axis="3.58252e-15 1 -3.2007e-16" type="hinge" range="-8.88178e-16 3.66519" actuatorfrcrange="-10 10"/>
          <geom pos="-0.0740001 -0.08025 -0.0174977" quat="1 0 0 0" type="mesh" rgba="0 0.4 0.6 1" mesh="link2"/>
          <body name="link3" pos="4.08431e-07 -0.0688 0.264" quat="1.32679489667753e-06 -8.00751986887921e-15 1.49750893756767e-14 -0.99999999999912">
            <inertial pos="-0.0556042 -0.0340514 -0.135083" quat="0.6673095083601458 -0.084819836562637807 0.734174327973797 0.092150265989044466" mass="0.982553" diaginertia="0.00087644191886574482 0.0076296046064632606 0.0076519794746709975"/>
            <joint name="joint3" pos="0 0 0" axis="4.54273e-15 1 1.04275e-14" type="hinge" range="0 3.14159" actuatorfrcrange="-10 10"/>
            <geom pos="-0.0740003 -0.0813 -0.281499" quat="1 0 0 0" type="mesh" rgba="0.552941 0.580392 0.203922 1" mesh="link3"/>
            <body name="link4" pos="-0.0600003 -0.0688 -0.244999" quat="1 1.47768000000004e-14 4.26186999999998e-14 -1.05292500000006e-14">
              <inertial pos="-0.0550959 0.032726 -0.0575534" quat="0.10060722133102602 0.94108569945662945 -0.079755596579730484 0.31284970530350165" mass="0.462165" diaginertia="0.00028778996544839548 0.00076643008992378317 0.00078788794462782174"/>
              <joint name="joint4" pos="0 0 0" axis="0 1 0" type="hinge" range="-1.69297 1.5708" actuatorfrcrange="-10 10"/>
              <geom pos="-0.0140003 -0.0125 -0.0364989" quat="1 0 0 0" type="mesh" rgba="0.545098 0.52549 0.419608 1" mesh="link4"/>
              <body name="link5" pos="-0.0405003 0.0338995 -0.0739989" quat="1 1.36632e-14 -2.16478000000001e-16 -4.1633349999997e-17">
                <inertial pos="0.0375847 -3.55003e-05 -0.000825911" quat="0.64668614070190811 0.64239183561513957 0.28865586152813083 -0.29292927229031912" mass="0.403307" diaginertia="0.00016964735642963316 0.00019568620481229821 0.00021979443875806869"/>
                <joint name="joint5" pos="0 0 0" axis="1 0 0" type="hinge" range="-1.5708 1.5708" actuatorfrcrange="-10 10"/>
                <geom pos="0.0265 -0.0463995 0.0375" quat="1 0 0 0" type="mesh" rgba="0.827451 0.623529 0.784314 1" mesh="link5"/>
                <body name="link6" pos="0.0404996 2.39858e-07 -0.0356" quat="1 4.41654500000011e-16 -2.94293999999983e-16 3.849305e-14">
                  <inertial pos="0 0 0" mass="1e-6" diaginertia="1e-9 1e-9 1e-9"/>
                  <joint name="joint6" pos="0 0 0" axis="1.46014e-15 2.40808e-14 -1" type="hinge" range="-2.0944 2.0944" actuatorfrcrange="-10 10"/>
                </body>
              </body>
            </body>
          </body>
        </body>
      </body>
    </body>
  </worldbody>
</mujoco>
