<mujoco model="crank_4310">
  <compiler angle="radian" meshdir="assets"/>

  <asset>
    <mesh name="gripper" file="gripper.stl"/>
    <mesh name="tip_left" file="tip_left.stl"/>
    <mesh name="tip_right" file="tip_right.stl"/>
  </asset>

  <worldbody>
    <body name="gripper" pos="0 0 0" quat="0.5 0.5 -0.5 -0.5">
      <inertial pos="0 -0.027 0" mass="0.45" diaginertia="0.0005 0.0004 0.0003"/>
      <geom pos="0 0.110597 -0.164101" quat="1 0 0 0" type="mesh" rgba="1 0.6 0 1" mesh="gripper" contype="0" conaffinity="0"/>
      <site name="tcp_site" pos="0 0 0" quat="0.5 0.5 0.5 -0.5" size="0.005" rgba="1 0 0 1"/>
      <site name="grasp_site" pos="0 -0.1347 0" quat="0.5 0.5 0.5 -0.5" size="0.005" rgba="0 1 0 1"/>
      <body name="tip_left" pos="-0.037 -0.0605 0.0392" quat="1 0 0 0">
        <inertial pos="0.03 -0.04 -0.039" mass="0.075" diaginertia="6e-5 6e-5 3e-5"/>
        <joint name="joint7" pos="0 0 0" type="slide" axis="1 0 0" range="0 0.039574"/>
        <geom pos="0.03495 0.171097 -0.203301" quat="1 0 0 0" type="mesh" rgba="0.74902 0.74902 0.74902 1" mesh="tip_left"/>
      </body>
      <body name="tip_right" pos="0.037 -0.0605 -0.0392" quat="1 0 0 0">
        <inertial pos="-0.03 -0.04 0.039" mass="0.075" diaginertia="6e-5 6e-5 3e-5"/>
        <joint name="joint8" pos="0 0 0" type="slide" axis="-1 0 0" range="0 0.039574"/>
        <geom pos="-0.03495 0.171097 -0.124901" quat="1 0 0 0" type="mesh" rgba="0.74902 0.74902 0.74902 1" mesh="tip_right"/>
      </body>
    </body>
  </worldbody>

  <equality>
    <joint joint1="joint7" joint2="joint8" polycoef="0 1 0 0 0"/>
  </equality>

  <contact>
    <exclude body1="gripper" body2="tip_left"/>
    <exclude body1="gripper" body2="tip_right"/>
    <exclude body1="tip_left" body2="tip_right"/>
  </contact>
</mujoco>
