<mujoco model="yam_ultra">
  <compiler angle="radian" meshdir="assets"/>

  <asset>
    <mesh name="base"  file="base.stl"/>
    <mesh name="link1" file="link1.stl"/>
    <mesh name="link2" file="link2.stl"/>
    <mesh name="link3" file="link3.stl"/>
    <mesh name="link4" file="link4.stl"/>
    <mesh name="link5" file="link5.stl"/>
  </asset>

  <worldbody>
    <body name="base" pos="0 0 0" quat="1 0 0 0">
      <inertial pos="-3.611e-05 2.26344e-05 0.0274792" quat="0.49954036332145396 0.50057947912270717 -0.49981383297991028 -0.5000657385342846" mass="0.940115" diaginertia="0.00081561760053630095 0.0016196011994023621 0.0018461202000613368"/>
      <geom pos="0.0374966 0.0464005 0.193801" quat="-7.3123010772031154e-14 -0.70710678118481629 -7.3123010771673112e-14 0.70710678118827863" type="mesh" rgba="0.317647 0.121569 0.498039 1" mesh="base"/>
      <body name="link1" pos="0 0 0.0733" quat="-7.3123010772031154e-14 -0.70710678118481629 -7.3123010771673112e-14 0.70710678118827863">
        <inertial pos="-0.0233636 -0.00172503 -0.00727828" quat="-0.6452436176973384 -0.21204348917963076 0.19681281961670494 0.70708057995669871" mass="0.101218" diaginertia="4.7181498384517786e-05 0.00010625072855078136 0.0001349130730647009"/>
        <joint name="joint1" pos="0 0 0" axis="-1 0 0" type="hinge" range="-2.61799 3.14159" actuatorfrcrange="-10 10"/>
        <geom pos="-0.119501 -0.0464 -0.0374968" quat="1 0 0 0" type="mesh" rgba="0.72549 0.45098 0.317647 1" mesh="link1"/>
        <body name="link2" pos="-0.0455 0.03285 -0.02" quat="1 -2.1066250000000002e-15 -1.804521180375e-29 4.9903099999999996e-15">
          <inertial pos="0.000134495 -0.0321253 0.129165" quat="-2.3381615529248389e-05 0.7071178193839055 -0.00013678541100874836 0.70709572919994479" mass="1.63122" diaginertia="0.00088839219885058791 0.01621030078414969 0.01628760001699971"/>
          <joint name="joint2" pos="0 0 0" axis="-3.58252e-15 -1 3.2007e-16" type="hinge" range="0 3.66519" actuatorfrcrange="-10 10"/>
          <geom pos="-0.0740001 -0.07925 -0.0174977" quat="1 0 0 0" type="mesh" rgba="0 0.4 0.6 1" mesh="link2"/>
          <body name="link3" pos="4.08431e-07 -0.0678 0.264" quat="1 -3.1000750000000002e-15 4.2795739409250002e-29 -2.53879e-15">
            <inertial pos="-0.0556042 0.0357986 -0.135083" quat="0.6673095083601458 -0.084819836562637627 0.73417432797379689 0.092150265989044328" mass="0.982553" diaginertia="0.00087644191886574482 0.0076296046064632606 0.0076519794746709975"/>
            <joint name="joint3" pos="0 0 0" axis="4.54273e-15 1 1.04275e-14" type="hinge" range="0 3.14159" actuatorfrcrange="-10 10"/>
            <geom pos="-0.0740003 -0.01145 -0.281499" quat="1 0 0 0" type="mesh" rgba="0.552941 0.580392 0.203922 1" mesh="link3"/>
            <body name="link4" pos="-0.0600003 0.0678 -0.244999" quat="1 5.21375e-15 -1.387780000001054e-17 -2.022025e-15">
              <inertial pos="-0.0548959 -0.0350242 -0.0575534" quat="0.10060722133102601 0.94108569945662934 -0.07975559657973047 0.31284970530350159" mass="0.462165" diaginertia="0.00028778996544839548 0.00076643008992378317 0.00078788794462782174"/>
              <joint name="joint4" pos="0 0 0" axis="0 1 0" type="hinge" range="-1.69297 1.5708" actuatorfrcrange="-10 10"/>
              <geom pos="-0.0138003 -0.0802502 -0.0364989" quat="1 0 0 0" type="mesh" rgba="0.545098 0.52549 0.419608 1" mesh="link4"/>
              <body name="link5" pos="-0.0403003 -0.0338507 -0.0703851" quat="1 -5.1092999999999996e-15 1.3877800000000156e-17 -3.0616149999999928e-17">
                <inertial pos="0.0375847 -3.55003e-05 -0.00717397" quat="0.64668614070190822 0.64239183561513957 0.28865586152813083 -0.29292927229031912" mass="0.403307" diaginertia="0.00016964735642963316 0.00019568620481229821 0.00021979443875806869"/>
                <joint name="joint5" pos="0 0 0" axis="1 0 0" type="hinge" range="-1.5708 1.5708" actuatorfrcrange="-10 10"/>
                <geom pos="0.0265 -0.0463995 0.0311519" quat="1 0 0 0" type="mesh" rgba="0.827451 0.623529 0.784314 1" mesh="link5"/>
                <body name="link6" pos="0.0404996 2.39858e-07 -0.0419481" quat="1 3.8111000000000064e-29 -2.6981499999999916e-29 2.212675e-15">
                  <inertial pos="0 0 0" mass="1e-6" diaginertia="1e-9 1e-9 1e-9"/>
                  <joint name="joint6" pos="0 0 0" axis="1.46014e-15 2.40808e-14 -1" type="hinge" range="-2.0944 2.0944" actuatorfrcrange="-10 10"/>
                </body>
              </body>
            </body>
          </body>
        </body>
      </body>
    </body>
  </worldbody>
</mujoco>
